Workbook

Sheet Start Here
B2: Crowsons Distribution - Wholesale Supplier Sourcing List
B3: 358 UK & EU suppliers for Amazon UK wholesale across 12 niches. Researched Oct 2026.
B5: What's new in this version
B6: Sorted Country > Category > Priority | C6: The Suppliers tab is sorted by Country A-Z, then Category A-Z within each country, then Amazon UK Demand (A first), then Priority. Country is the first column and each country is shaded in alternating bands, so you can work through one country - and one niche - at a time. Pan-European / online platforms are at the bottom.
B7: NEW: Top Picks tab + Amazon UK Demand | C7: Start with the Top Picks tab: the suppliers whose brands are household names that already sell well on Amazon UK (A-rated). Every supplier now has an 'Amazon UK Demand' rating - A Strong (green), B Moderate (yellow), C Low / little UK demand (grey) - and within each country and niche the A-rated suppliers are listed first. Filter the Suppliers tab on A or B to skip small local brands with little UK demand.
B8: Low Priority tab + 2nd scam check | C8: Priority 1-2 suppliers (weak Amazon fit, marketplaces, retailers, capped after the scam check) have moved off the Suppliers tab to a separate 'Low Priority' tab, so the main list is priority 3-5 only. A second check scanned 2025-26 insolvency notices and EU Safety Gate alerts: Tunturi was removed (parent Accell Group declared bankrupt Aug 2026) and INGLOT and La Rive were flagged CAUTION.
B9: Anti-scam check | C9: Every wholesaler, trader and marketplace was checked against company registers (Companies House, KvK, KRS, ARES, SIREN...), insolvency notices, regulator fines and independent reviews. 25 suppliers failed (liquidation, dissolved, administration, fines, or no evidence the business exists) and were moved to the 'Removed - Failed Check' tab. Every remaining supplier has a 'Scam Check' result: PASS (green), CHECK (yellow - limited public info, verify before paying) or CAUTION (orange - specific risk noted). The Contact First tab now only lists PASS suppliers.
B10: Quality check | C10: Every supplier was re-checked: missing phone numbers, emails, addresses and registry IDs were filled in for ~30 suppliers; 3 suppliers with no verifiable contact or registration were removed; websites we could not confirm are now a click-to-search link; and a new 'Contact First' tab lists the best EU suppliers with a direct phone/email, cheapest countries first.
B11: Round 5: cheapest-country sourcing | C11: Round 5 targets the EU countries where stock is cheapest to buy - mainly Poland, Czech Republic, Bulgaria, Romania, the Baltics, Portugal and Greece - and their home-grown manufacturers. Most Round 5 suppliers are verified through a government export agency (CzechTrade, Poland's trade.gov.pl, Bulgarian/Lithuanian registries) or a major trade fair, which is the best protection against fake 'wholesalers'. Round 5 rows are shaded green in the Company column.
B12: Country Price Level column + Best-Value Countries tab | C12: Each supplier now shows whether its country is Low-cost, Mid or Higher for buying stock. The new Best-Value Countries tab lists, for every niche, the cheapest EU countries to source from, why, and how many suppliers you already have there.
B13: Round 4: quality-filtered EU brands | C13: Round 4 added EU-only suppliers that passed a strict quality bar: identifiable company + proof of establishment (trade-fair exhibitor, official registry, years trading or recognised brand) + a usable contact route. Weak / directory-only leads were left out.
B14: Country Index tab | C14: Lists every country with supplier counts - click 'Go to' to jump straight to that country's first row.
B15: Also operates in | C15: New column showing other countries a supplier covers (the Country column now holds one main country so the grouping works).
B16: Keeping your tracker notes | C16: If you already filled in the tracker in the previous file, copy the yellow columns across by matching the Company name - or send me the old file and I'll merge it.
B18: How to use this workbook
B19: 1. Suppliers | C19: The master list, grouped by Country A-Z, then Category A-Z, then Priority (5 = best fit for Amazon). Use the filter arrows to filter by Category, Country, Priority or Added.
B20: 0. Top Picks | C20: START HERE: suppliers of brands with proven Amazon UK demand, grouped by niche, with direct contact details and a link to the full row.
B21: 1a. Low Priority | C21: Priority 1-2 suppliers kept for reference only - weaker Amazon fit or higher risk. Use only once the main list is worked through.
B22: 1b. Country Index | C22: Jump to any country's block of suppliers with one click.
B23: 1d. Contact First | C23: Your shortlist: every priority 4-5 EU supplier with a direct phone/email, cheapest countries first. Start your outreach here.
B24: 1c. Best-Value Countries | C24: For each niche: the cheapest EU countries to buy from, why, and how many low-cost-country suppliers you already have. Plus anti-scam checks.
B25: 2. Yellow columns | C25: Your outreach tracker. Status, Method and Account Approved have drop-down lists. 'Suggested Follow-up' fills in automatically (5 working days after Date Contacted) and turns red when overdue.
B26: 3. LinkedIn Outreach | C26: One-click LinkedIn searches for each company page and its sales / account-manager staff, plus a tracker.
B27: 4. Niche Guide | C27: Read before contacting suppliers in a new niche - it lists the compliance documents to ask for.
B28: 5. Profit Calculator | C28: Check every product before ordering. Blue cells are inputs; black cells are formulas.
B29: 6. Templates | C29: Copy-paste first-contact email, follow-up, LinkedIn notes and invoice / ungating request.
B30: 7. Dashboard | C30: Live counts by niche, region and outreach status.
B31: 8. Find More Suppliers / Due Diligence | C31: Directories & trade shows to keep growing the list, and a checklist to vet suppliers before paying.
B33: Priority score (1-5)
B34: 5 | C34: Established, branded stock, sells to online / Amazon sellers or provides invoices suitable for ungating. Contact first.
B35: 4 | C35: Established and branded, but may have higher MOQs, selective accounts or a narrower range.
B36: 3 | C36: Credible, worth contacting - confirm terms, online-selling policy and invoice details.
B37: 2 | C37: Lower fit (territory-limited, pro-only brands, limited info) or larger-scale target for later.
B38: 1 | C38: Low confidence, known red flag, or not suitable for Amazon - kept so you know to avoid / verify.
B40: Data confidence
B41: Official / company website | C41: Details came from the supplier's own site or an official register (Companies House, KRS, MHRA, LEI).
B42: Directory / press / trade show | C42: From trade press, exhibitor lists or business directories - confirm on the company website before relying on them.
B43: Marketplace / unverified | C43: Self-published profile only. Verify registration (Companies House / KvK / KRS / VIES VAT) before engaging.
B44: Blank cells | C44: Not publicly available. MOQs are usually only shared once a trade account is approved - ask in your first email.
B46: Key Amazon UK considerations
...

Sheet Top Picks
A1: Top Picks - suppliers of brands that already sell well on Amazon UK
A2: 55 suppliers whose brands are household names with established, well-selling Amazon UK listings - so you can join existing listings instead of building demand. Grouped by Category, best priority first. Demand is our estimate: check each ASIN on Keepa / SellerAmp (sales rank, number of sellers, Amazon on the listing) before ordering, and watch for brand-gated listings.
A4: Category | B4: Priority | C4: Company | D4: Country | E4: Supplier Type | F4: Key Brands / Products | G4: Amazon Fit Notes | H4: Phone | I4: Email | J4: Website | K4: Scam Check | L4: Go to row
A5: B2B Marketplace | B5: 5 | C5: Qogita | D5: UK | E5: B2B wholesale marketplace | F5: 10k+ brands, 500k+ products from 500+ vetted suppliers - health, beauty, fragrance, household | G5: Provides commercial invoices that can support ungating - built for Amazon sellers | I5: via website | J5: https://www.qogita.com | K5: PASS - well-known company: VC-backed European B2B wholesale platform. | L5: Go to row
A6: Baby Products | B6: 5 | C6: Babybase Ltd | D6: UK | E6: Wholesaler / UK distributor | F6: Tommee Tippee, MAM, Shnuggle, Munchkin, Matchstick Monkey, My Buggy Buddy | G6: Multi-brand, low MOQ - strong fit; ask about marketplace policy | H6: +44 1886 887758 | I6: sales@babybase.co.uk | J6: https://www.babybase.co.uk | K6: PASS (checked) - Companies House 01475315 active since 1980. | L6: Go to row
A7: Baby Products | B7: 4 | C7: Béaba Group (incl. Childhome) | D7: France | E7: Brand owner / distributor | F7: Béaba Babycook, feeding, hygiene, sleep; Childhome; distributes iCandy (FR/Benelux) | G7: Babycook is a strong Amazon seller; also on Qogita | J7: https://www.beaba.com | K7: PASS - established brand / group | L7: Go to row
A8: Baby Products | B8: 4 | C8: MAPA GmbH (NUK) | D8: Germany | E8: Brand owner / manufacturer | F8: NUK bottles & dummies, Fresh Fruit feeders; also Billy Boy, household gloves | G8: NUK is a top Amazon baby brand | J8: https://www.mapa.de | K8: PASS - company register entry | L8: Go to row
A9: Baby Products | B9: 3 | C9: MAM Babyartikel GmbH | D9: Germany | E9: Brand distributor (MAM Baby AG subsidiary) | F9: MAM dummies, bottles, teethers, feeding | G9: Official brand source = best possible invoices | H9: +49 4263 9317 0 | J9: https://www.mambaby.com | K9: PASS - established brand / group | L9: Go to row
A10: Baby Products | B10: 3 | C10: Artsana S.p.A. (Chicco, Boppy) | D10: Italy | E10: Brand owner / manufacturer | F10: Chicco baby feeding, toys, nursery; Boppy; Control (health) | G10: Buy UK stock via RKW | H10: +39 031 382790 (verify) | J10: https://www.artsana.com | K10: PASS - established brand / group | L10: Go to row
A11: Beauty | B11: 4 | C11: cosnova GmbH (essence, CATRICE) | D11: Germany | E11: Brand owner (direct + local distributors) | F11: essence, CATRICE, Physicians Formula (EU) | G11: essence & CATRICE are top Amazon beauty sellers - may route you to UK distributor | H11: +49 6196 76156-0 | I11: service@cosnova.eu | J11: https://www.cosnova.com | K11: PASS - well-known company: Owner of essence & CATRICE - one of Europe's largest make-up brands. | L11: Go to row
A12: Beauty | B12: 4 | C12: Weleda AG (German branch) | D12: Germany | E12: Brand owner / manufacturer | F12: Weleda natural skincare, baby care (Calendula), Skin Food | G12: Skin Food is a strong Amazon seller | I12: dialog@weleda.de | J12: https://www.weleda.de | K12: PASS - established brand / group | L12: Go to row
A13: Beauty | B13: 3 | C13: QudoBeauty | D13: Romania | E13: K-beauty B2B wholesaler | F13: COSRX, Beauty of Joseon + other Korean skincare (CPNP-registered) | G13: K-beauty (COSRX, Beauty of Joseon) is a top Amazon UK beauty seller - check brand gating | H13: +40 742 372 490 | I13: emy@qudobeauty.com | J13: https://qudobeauty.com | K13: CAUTION - Launched 2025; legal entity not confirmed - get CUI/VAT number before ordering. | L13: Go to row
A14: DIY & Tools | B14: 5 | C14: Toolbank Ltd | D14: UK | E14: Trade-only wholesale distributor | F14: DeWalt, Milwaukee, HiKoki, Metabo, Black+Decker, Olympia + hand tools, fixings, consumables | G14: Ask about online/marketplace reseller policy - branded power tools need care on price (MAP) | H14: +44 344 463 6001 | J14: https://www.toolbank.com | K14: PASS - company register entry | L14: Go to row
A15: DIY & Tools | B15: 4 | C15: Fiskars Group (Fiskars Finland Oy Ab) | D15: Finland | E15: Brand owner (listed) | F15: Fiskars garden tools, axes, scissors; also Gerber, Iittala (home) | G15: Fiskars is a top Amazon garden brand | J15: https://www.fiskarsgroup.com | K15: PASS - listed company | L15: Go to row
A16: DIY & Tools | B16: 4 | C16: Einhell Germany AG | D16: Germany | E16: Brand owner (listed) | F16: Einhell Power X-Change cordless tools, garden tools, workshop | G16: Huge Amazon brand; lithium batteries = hazmat docs | I16: via website contact form | J16: https://www.einhell.com/einhell-worldwide/ | K16: PASS - listed company | L16: Go to row
A17: DIY & Tools | B17: 4 | C17: fischerwerke GmbH & Co. KG | D17: Germany | E17: Brand owner / manufacturer | F17: fischer wall plugs, anchors & fixings; fischertechnik | G17: Fixings kits sell well | H17: +49 7443 120 | J17: https://www.fischer.de | K17: PASS - well-known company: fischer - world-leading German fixings manufacturer (120+ countries). | L17: Go to row
A18: DIY & Tools | B18: 4 | C18: GARDENA Deutschland GmbH (Husqvarna Group) | D18: Germany | E18: Brand owner | F18: GARDENA hoses, watering, garden tools, robotic mowers | G18: Strong Amazon garden brand | H18: +49 731 490-0 | I18: service@gardena.com | J18: https://www.gardena.com | K18: PASS - established brand / group | L18: Go to row
A19: DIY & Tools | B19: 4 | C19: KNIPEX-Werk C. Gustav Putsch KG | D19: Germany | E19: Brand owner / manufacturer | F19: KNIPEX pliers, Cobra, wire strippers | G19: KNIPEX Cobra pliers are top sellers; brand may be gated | H19: +49 202 4794-0 | I19: info@knipex.de | J19: https://www.knipex.com | K19: PASS - major trade-fair exhibitor | L19: Go to row
A20: DIY & Tools | B20: 4 | C20: Wera Werkzeuge GmbH | D20: Germany | E20: Brand owner / manufacturer | F20: Wera screwdrivers, bits, ratchets, Kraftform | G20: Wera sells very well on Amazon UK | H20: +49 202 4045-322 | I20: info@wera.de | J20: https://www.wera.de | K20: PASS - established brand / group | L20: Go to row
A21: DIY & Tools | B21: 4 | C21: Wiha Werkzeuge GmbH | D21: Germany | E21: Brand owner / manufacturer | F21: Wiha screwdrivers, VDE insulated tools, bits | H21: +49 7722 959-0 | I21: info.de@wiha.com | J21: https://www.wiha.com | K21: PASS - well-known company: Major German hand-tool manufacturer. | L21: Go to row
A22: DIY & Tools | B22: 4 | C22: Draper Tools | D22: UK | E22: Brand owner / distributor (stockist programme) | F22: Draper, Draper Expert, Draper Tools + 1000s of tool & garage lines | G22: Brand-direct invoices; check stockist terms on online pricing | H22: +44 23 8049 4333 (orders) | I22: orders@drapertools.com | J22: https://www.drapertools.com | K22: PASS - established brand / group | L22: Go to row
A23: DIY & Tools | B23: 3 | C23: Campbell Miller Tools | D23: UK | E23: Bosch distributor | F23: Bosch (UK's largest Bosch distributor) + trade tools | J23: https://bosch-pt.com/uk_bssdealer/uk/en/start/bss_acct/dealers_list/campbell_miller.htm | K23: PASS (checked) - Campbell Miller (Tools) Ltd SC034278, active since 1959. | L23: Go to row
A24: Fragrance | B24: 5 | C24: Knights Fragrances | D24: UK | E24: Wholesaler / Distributor | F24: Prestige & mass-market branded fragrances | G24: Supplies online retailers - good fit | J24: https://www.knights-fragrances.co.uk | K24: CAUTION - Directory info only (since 1984, 11-50 staff) - confirm Companies House number. | L24: Go to row
A25: Fragrance | B25: 4 | C25: BJUTIP a.s. | D25: Czech Republic | E25: Distributor | F25: Armaf, Afnan, Lattafa, Paris Corner, French Avenue, Khadlaj, Maison Asrar + others | G25: Has an e-commerce seller programme - Arabian brands popular & often easier to list on Amazon | H25: +420 724 076 367 | I25: sales@bjutip.com (wholesale); info@bjutip.com | J25: https://www.bjutip.com | K25: CAUTION - Registered (IČO 10865373) but young (2021) and sells heavily-counterfeited Arabian brands - ask for brand authorisation letters. | L25: Go to row
A26: Fragrance | B26: 4 | C26: Shaneel Group (Shaneel Enterprises Ltd) | D26: UK | E26: Wholesaler / Distributor / Brand owner | F26: Branded fragrance supply; group incl. Mayfair Perfumes, Designer Parfums, Worth Paris, DDF Skincare | G26: Owns some brands - ask about brand authorisation for those | J26: https://www.shaneel.com/shaneel-enterprises | K26: PASS (checked) - Companies House 02171783 active since 1987 (perfume & cosmetics wholesale). | L26: Go to row
A27: Fragrance | B27: 3 | C27: Emporium Handels & Vertriebs GmbH (B&S Group) | D27: Germany | E27: Wholesaler | F27: 8,000+ perfume & cosmetics products | K27: PASS - established brand / group | L27: Go to row
A28: Fragrance | B28: 3 | C28: MisterM Plus Sp. z o.o. Sp.k. | D28: Poland | E28: Wholesaler / Exporter | F28: Coty, P&G, Reckitt Benckiser - perfumes, cosmetics, hygiene | G28: FMCG brands (P&G/Coty) - strong Amazon sellers | K28: PASS (checked) - KRS-registered; no insolvency or complaints found. | L28: Go to row
A29: General Wholesale / FMCG | B29: 4 | C29: West Coast Supply Group | D29: Netherlands | E29: A-brand FMCG distributor | F29: A-brands: personal care, beauty, home care, food, drinks, medical, electronics | G29: A-brand FMCG - strong Amazon sellers | I29: sales@westcoastsupplygroup.com | J29: https://www.westcoastsupplygroup.com | K29: PASS (checked) - 40+ years; ~200 staff; active in 75 countries. | L29: Go to row
A30: General Wholesale / FMCG | B30: 4 | C30: Booker Wholesale (incl. Makro UK) | D30: UK | E30: Cash & carry / delivered wholesale | F30: Grocery, household, health & beauty, confectionery, pet | G30: Fine for invoices; margins tight - use promo deals | J30: https://www.booker.co.uk | K30: PASS - established brand / group | L30: Go to row
A31: General Wholesale / FMCG | B31: 3 | C31: Costco UK (Business Membership) | D31: UK | E31: Warehouse club | F31: Grocery, household, health & beauty, toys, electronics | G31: Business membership allows resale; receipts show Costco details | H31: +44 1923 830477 (Central Membership) | J31: https://www.costco.co.uk | K31: PASS - well-known company: Costco - global warehouse club. | L31: Go to row
A32: Health & Personal Care | B32: 5 | C32: Harrisons Direct (Albert Harrison & Co Ltd) | D32: UK | E32: Wholesaler | F32: Health & beauty, GSL medicines (pain relief, hay fever), toiletries, household | G32: Branded FMCG lines - good for wholesale arbitrage; note Amazon rules on medicines | H32: +44 1254 306840 | J32: https://www.harrisonsdirect.co.uk | K32: PASS (checked) - MHRA wholesale authorisation UK WDA(H) 2530; trading since 1919. | L32: Go to row
A33: Health & Personal Care | B33: 4 | C33: Beurer GmbH (Beurer UK Ltd) | D33: Germany | E33: Brand owner with UK subsidiary | F33: Beurer BP monitors, thermometers, massagers, scales, TENS, beauty devices | G33: Huge Amazon health-device brand; check UK account terms | H33: +49 731 3989-0 | J33: https://www.beurer.com/uk/facts/ | K33: PASS - established brand / group | L33: Go to row
A34: Health & Personal Care | B34: 4 | C34: TePe Munhygienprodukter AB | D34: Sweden | E34: Brand owner / manufacturer | F34: TePe interdental brushes, toothbrushes, oral care | G34: Interdental brushes are strong repeat sellers | H34: +46 40 670 11 00 | I34: info@tepe.com | J34: https://tepe.com/global/contact | K34: PASS - established brand / group | L34: Go to row
A35: Health & Personal Care | B35: 3 | C35: MEDISANA AG | D35: Germany | E35: Brand owner | F35: Medisana BP monitors, inhalers, massagers, scales, heated blankets | G35: Also on Qogita (low MOV) | H35: +49 2131 3668-0 | I35: info@medisana.de | J35: https://www.medisana.de | K35: PASS - established brand / group | L35: Go to row
A36: Home & Kitchen | B36: 5 | C36: RKW Ltd (Sutton Venture Group) | D36: UK | E36: Brand owner / distributor | F36: Tower, Swan, Goblin, Redring, Wade, Royal Victoria, Burco; exclusive Smeg SDA distributor | G36: Tower & Swan are big Amazon UK sellers - brand-direct invoices | H36: +44 333 220 6070 | I36: sales@rkwltd.com | J36: https://www.rkwltd.com | K36: PASS - major trade-fair exhibitor | L36: Go to row
A37: Home & Kitchen | B37: 4 | C37: Bialetti Industrie S.p.A. | D37: Italy | E37: Brand owner (listed) | F37: Bialetti moka pots & coffee, Rondine & Aeternum cookware, Girmi appliances | G37: Moka pots are evergreen Amazon sellers | H37: +39 030 7720011 | J37: https://www.bialetti.it | K37: PASS - listed company | L37: Go to row
A38: Home & Kitchen | B38: 4 | C38: EPE International Ltd | D38: UK | E38: Distributor (housewares & SDA) | F38: Kenwood, De'Longhi, Kärcher, Philips, Braun (food prep/laundry), Salter, Tefal/Jamie Oliver cookware | J38: https://www.epeinternational.com | K38: PASS (checked) - Companies House 04897647; 20+ years; BHETA & Bira member. | L38: Go to row
A39: Home & Kitchen | B39: 3 | C39: Leifheit AG | D39: Germany | E39: Brand owner (listed company) | F39: Leifheit, Soehnle - cleaning, laundry, kitchen, scales | G39: Brand-direct; very popular on Amazon (may have MAP rules) | J39: https://www.leifheit.com | K39: PASS - listed company | L39: Go to row
A40: Home & Kitchen | B40: 3 | C40: Wolfsohn | D40: Germany | E40: Branded electronics & household wholesaler | F40: 6,000+ SKUs in stock: Braun, Philips, Samsung, Xiaomi, QCY, PoundMax | J40: https://www.ifa-berlin.com/exhibitors/wolfsohn | K40: PASS (checked) - IFA Berlin exhibitor; 6,000+ branded SKUs in stock. | L40: Go to row
A41: Home & Kitchen | B41: 3 | C41: Keter Luxembourg SARL (Curver) | D41: Luxembourg | E41: Brand owner / manufacturer | F41: Curver storage boxes & baskets, Keter | G41: Storage boxes sell well but are bulky - check FBA fees | H41: +352 52 47 17 773 | J41: https://www.curver.com | K41: PASS - major trade-fair exhibitor | L41: Go to row
...

Sheet Suppliers
A1: Country | B1: ID | C1: Priority (1-5) | D1: Category | E1: Company | F1: Amazon UK Demand | G1: Website | H1: City / Region | I1: Also operates in | J1: Region | K1: Country Price Level | L1: Address | M1: Phone | N1: Email | O1: Supplier Type | P1: Key Brands / Products | Q1: Segment | R1: MOQ / Min. Order | S1: Account Requirements | T1: Ships to UK? | U1: Sells to Online/Amazon Sellers? | V1: Dropship? | W1: Registry ID | X1: Legitimacy Evidence | Y1: Amazon Fit Notes | Z1: Notes / Red Flags | AA1: Data Confidence | AB1: Scam Check (Oct 2026) | AC1: Source | AD1: LinkedIn Company Search | AE1: Added | AF1: Status | AG1: Date Contacted | AH1: Method | AI1: Contact Name | AJ1: Response / Notes | AK1: Suggested Follow-up | AL1: Account Approved? | AM1: Next Step
A2: Austria | B2: 1 | C2: 3 | D2: Stationery & Office | E2: KORES GmbH | F2: B - Moderate | G2: https://www.kores.com | H2: Vienna | J2: EU / Europe | K2: Higher | L2: Leopold-Ungar-Platz 2/Top 334, 1190 Wien | O2: Brand owner / manufacturer | P2: Kores glue sticks, correction tape, office & school supplies, printer supplies | Q2: Office & school supplies | R2: Account based | S2: Distributors & retailers | T2: Sold in 80+ countries - ask | U2: Unknown | V2: Unknown | X2: Advantage Austria company profile; production in CZ & MX | AA2: Government trade agency + company catalogue | AB2: PASS - government export agency / trade body listing | AC2: Source link | AD2: Search LinkedIn | AE2: Round 4 | AF2: Not contacted | AK2: =IF(AG2="","",WORKDAY(AG2,5))
A3: Austria | B3: 2 | C3: 3 | D3: Toys & Games | E3: Stadlbauer Marketing + Vertrieb GmbH | F3: B - Moderate | G3: https://www.stadlbauer.at | H3: Puch bei Hallein (Salzburg) | J3: EU / Europe | K3: Higher | L3: Rennbahn Allee 1, 5412 Puch bei Hallein | O3: Distributor & brand owner | P3: Exclusive Playmobil (Austria); Carrera, Pustefix, Schildkröt, Bburago, Disney & Nintendo licences | Q3: Branded toys | R3: Account based | S3: Retailers (DACH) | T3: DACH territory | U3: Unknown | V3: Unknown | X3: Part of Carrera Revell group (Quantum Capital) since 2019 | Y3: Useful for Amazon.de | AA3: Investor announcement + press | AB3: PASS - established brand / group | AC3: Source link | AD3: Search LinkedIn | AE3: Round 4 | AF3: Not contacted | AK3: =IF(AG3="","",WORKDAY(AG3,5))
A4: Austria | B4: 3 | C4: 3 | D4: Toys & Games | E4: Wiener Spielkartenfabrik Ferd. Piatnik & Söhne | F4: B - Moderate | G4: https://www.piatnik.com | H4: Vienna | J4: EU / Europe | K4: Higher | L4: Vienna | O4: Brand owner / manufacturer | P4: Piatnik playing cards, Activity, puzzles, party games | Q4: Games & puzzles | R4: On request | S4: Retailers & distributors | T4: Exports 80% of output to 72 countries - ask | U4: Unknown | V4: Unknown | X4: 200-year-old Austrian company; featured by Advantage Austria (gov trade agency) | AA4: Government trade agency article | AB4: PASS - government export agency / trade body listing | AC4: Source link | AD4: Search LinkedIn | AE4: Round 4 | AF4: Not contacted | AK4: =IF(AG4="","",WORKDAY(AG4,5))
A5: Belgium | B5: 4 | C5: 4 | D5: DIY & Tools | E5: Varo (Vic Van Rompuy NV) | F5: C - Low / little UK demand | G5: https://varo.com/contact | H5: Lier | J5: EU / Europe | K5: Higher | L5: Joseph Van Instraat 9, 2500 Lier | M5: +32 3 292 92 90 | N5: info@varo.com | O5: Brand owner / distributor | P5: Powerplus, Kreator, Premion tools & garden equipment | Q5: Power & garden tools | R5: On request | S5: Retailers & distributors | T5: Sold across Europe - ask | U5: Unknown | V5: Unknown | X5: Sold via major EU DIY chains & e-tailers (Bricomarché, Alza) | Y5: Budget-friendly tool brands suit Amazon | AA5: Company website (via search) | AB5: PASS - well-known company: Belgian tool group (Powerplus, Silverline Benelux) - established brand owner. | AC5: Source link | AD5: Search LinkedIn | AE5: Round 4 | AF5: Not contacted | AK5: =IF(AG5="","",WORKDAY(AG5,5))
A6: Belgium | B6: 5 | C6: 3 | D6: Fragrance | E6: Beautylux | F6: B - Moderate | G6: https://www.beautylux.be | H6: Brussels (Schaerbeek) | J6: EU / Europe | K6: Higher | L6: Rue François Bossaerts, Schaerbeek, Brussels (confirm) | M6: +32 2 732 .... (see website) | O6: Importer / Distributor | P6: Pure Altitude, Berdoues, Ariana Grande, Bentley + others; 2,500+ refs | Q6: Designer / celebrity fragrance | R6: On request | S6: Retail accounts | T6: Check | U6: Unknown | V6: Unknown | X6: Established 1980; 450+ points of sale in Benelux | Y6: Official importer for some brands - good invoices | AA6: Directory - confirm on website | AB6: CAUTION - Since 1980 per directories, but Belgian enterprise number not confirmed. | AC6: Source link | AD6: Search LinkedIn | AE6: Round 1 | AF6: Not contacted | AK6: =IF(AG6="","",WORKDAY(AG6,5))
A7: Belgium | B7: 6 | C7: 3 | D7: Home & Kitchen | E7: Galico NV | F7: C - Low / little UK demand | G7: https://galico.be | H7: Vichte (West Flanders) | J7: EU / Europe | K7: Higher | L7: Oudenaardestraat 49b, B-8570 Vichte | M7: +32 56 62 69 69 | N7: info@galico.be | O7: Brand owner / distributor | P7: Escalo (ladders), Practo Home (storage), Practo Garden, Casibel (household); distributes Grosfillex, Mottez, Garantia, Kendo tools | Q7: Household, storage, ladders, garden, hand tools | R7: On request | S7: Retailers (BE/FR/LU) | T7: Ask | U7: Unknown | V7: Unknown | W7: BE 0453.670.483 | X7: VAT BE 0453.670.483; B2B portal | Y7: Own brands = direct invoices | Z7: Also covers DIY (Kendo hand tools, Escalo ladders). | AA7: Company website (via search) | AB7: PASS - well-known company: Established Belgian housewares brand owner/distributor. | AC7: Source link | AD7: Search LinkedIn | AE7: Round 2 | AF7: Not contacted | AK7: =IF(AG7="","",WORKDAY(AG7,5))
A8: Belgium | B8: 7 | C8: 4 | D8: Pet Supplies | E8: Savic NV | F8: B - Moderate | G8: https://www.savic.be | H8: Heule (Kortrijk) | J8: EU / Europe | K8: Higher | L8: Ringlaan 10, 8501 Heule | M8: +32 65 35 33 45 | N8: info@savic.be (verify) | O8: Brand owner / manufacturer | P8: Savic small-animal cages, cat litter trays, dog & bird products | Q8: Pet habitats & accessories | R8: On request | S8: Distributors & retailers | T8: Sold in 73-80+ countries - ask | U8: Unknown | V8: Unknown | X8: Family business; Interzoo exhibitor; Head of Intl Sales Pascal Nichelson | AA8: Trade directories + trade fair | AB8: PASS - major trade-fair exhibitor | AC8: Source link | AD8: Search LinkedIn | AE8: Round 4 | AF8: Not contacted | AK8: =IF(AG8="","",WORKDAY(AG8,5))
A9: Belgium | B9: 8 | C9: 4 | D9: Pet Supplies | E9: Flamingo Pet Products NV | F9: C - Low / little UK demand | G9: https://www.flamingo.be/en/for-companies | H9: Olen | J9: EU / Europe | K9: Higher | L9: Lammerdries-Winkelstraat 25, 2250 Olen | M9: +32 14 25 84 80 | N9: info@flamingo.be | O9: Wholesaler / manufacturer | P9: Flamingo - 10,000+ pet products; private label available | Q9: Pet accessories & toys | R9: On request | S9: Companies - B2B section on website | T9: Ask | U9: Unknown | V9: Unknown | X9: Interzoo & Zoomark exhibitor; long-established | AA9: Trade show listings | AB9: PASS - major trade-fair exhibitor | AC9: Source link | AD9: Search LinkedIn | AE9: Round 2 | AF9: Not contacted | AK9: =IF(AG9="","",WORKDAY(AG9,5))
A10: Belgium | B10: 9 | C10: 3 | D10: Pet Supplies | E10: Laroy Group (Duvo+) | F10: C - Low / little UK demand | G10: Not confirmed - click to search | H10: Wondelgem (Ghent) | J10: EU / Europe | K10: Higher | L10: Industrieweg 98-100, 9032 Wondelgem | M10: +32 9 258 13 00 (verify) | O10: Manufacturer & distributor | P10: Duvo+, Witte Molen, CéDé - 10,000+ products | Q10: Pet food & accessories | R10: On request | S10: Pet shops & international trade partners | T10: Ask | U10: Unknown | V10: Unknown | X10: Major Belgian pet group (Laroy Duvo + CéDé + Witte Molen) | AA10: Trade press | AB10: PASS - established brand / group | AC10: Source link | AD10: Search LinkedIn | AE10: Round 3 | AF10: Not contacted | AK10: =IF(AG10="","",WORKDAY(AG10,5))
A11: Belgium | B11: 10 | C11: 3 | D11: Pet Supplies | E11: Moderna Products NV | F11: C - Low / little UK demand | G11: https://www.modernaproducts.com | H11: Izegem | J11: EU / Europe | K11: Higher | L11: Zuidkaai 35, 8870 Izegem | O11: Manufacturer & distributor | P11: Moderna litter boxes, bowls, carriers, storage (also private label) | Q11: Pet plastics | R11: On request | S11: Distributors & retailers | T11: Exports to 60-79 countries - ask | U11: Unknown | V11: Unknown | X11: 3rd-generation family business; production in BE & US; Interzoo exhibitor | AA11: Trade fair listing | AB11: PASS - major trade-fair exhibitor | AC11: Source link | AD11: Search LinkedIn | AE11: Round 4 | AF11: Not contacted | AK11: =IF(AG11="","",WORKDAY(AG11,5))
A12: Belgium | B12: 11 | C12: 3 | D12: Pet Supplies | E12: Vadigran NV | F12: C - Low / little UK demand | G12: https://www.vadigran.com | H12: Ghislenghien | J12: EU / Europe | K12: Higher | L12: Chemin Preuscamps 20B, 7822 Ghislenghien (BE0431.312.379) | M12: +32 68 26 96 40 | O12: Distributor / manufacturer | P12: ~6,000 pet products (food & accessories) in 40 countries | Q12: Pet food & accessories | R12: On request | S12: Retailers; currently recruiting distributors | T12: Ask | U12: Unknown | V12: Unknown | W12: BE0431.312.379 | X12: Interzoo exhibitor; Belgian registry | Z12: Actively recruiting distributors. | AA12: Trade directory + registry + trade fair | AB12: PASS - company register entry | AC12: Source link | AD12: Search LinkedIn | AE12: Round 4 | AF12: Not contacted | AK12: =IF(AG12="","",WORKDAY(AG12,5))
A13: Bulgaria | B13: 12 | C13: 4 | D13: Beauty | E13: Bulgarian Rose AD (Bulgarska Roza Karlovo) | F13: C - Low / little UK demand | G13: Not confirmed - click to search | H13: Karlovo | J13: EU / Europe | K13: Low-cost | L13: Industrial Zone 1, 4300 Karlovo | N13: Via official distributor Cosmetics Bulgaria (cosmeticsbulgaria.com) | O13: Manufacturer (listed) | P13: Bulgarian Rose rose-oil skincare, hair & body care | Q13: Rose cosmetics | R13: On request | S13: Export to 40+ countries; distributors | T13: Ask | U13: Unknown | V13: Unknown | W13: EIK 115009344 | X13: Listed on Bulgarian Stock Exchange; EIK 115009344; Stara Planina Hold group; founded 1948 | Y13: Rose skincare at very low unit cost - good margin on gift sets | AA13: Stock exchange profile + business registry | AB13: PASS - listed company | AC13: Source link | AD13: Search LinkedIn | AE13: Round 5 | AF13: Not contacted | AK13: =IF(AG13="","",WORKDAY(AG13,5))
A14: Bulgaria | B14: 13 | C14: 3 | D14: Beauty | E14: Lema Kazanlak (rose distillery) | F14: C - Low / little UK demand | G14: http://www.lemabg.com | H14: Kazanlak | J14: EU / Europe | K14: Low-cost | L14: Southern Industrial Zone, Kazanlak | O14: Producer / manufacturer | P14: Lema rose oil, rose water, rose cosmetics | Q14: Rose water & oils | R14: On request | S14: Direct inquiry | T14: Ask | U14: Unknown | V14: Unknown | X14: Listed by the Bulgarian Ministry of Tourism; own Rosa Damascena plantations | Y14: Rose water toners sell well; check cosmetics compliance (UK RP / CPNP) | Z14: Make sure UK cosmetics labelling and a Responsible Person are in place | AA14: Government tourism listing + distributor page | AB14: PASS - government export agency / trade body listing | AC14: Source link | AD14: Search LinkedIn | AE14: Round 5 | AF14: Not contacted | AK14: =IF(AG14="","",WORKDAY(AG14,5))
A15: Bulgaria | B15: 14 | C15: 3 | D15: Home & Kitchen | E15: Parmash AD | F15: C - Low / little UK demand | G15: Not confirmed - click to search | H15: Sliven | J15: EU / Europe | K15: Low-cost | L15: Debela Koria, Stopanski dvor 1, 8800 Sliven | M15: +359 44 667 308 | O15: Manufacturer | P15: Clothes dryers/airers, ironing boards, plate racks, household ladders | Q15: Laundry & household | R15: On request | S15: Retail chains in BG, DE, RO, IT, RS, MK | T15: Ask | U15: Unknown | V15: Unknown | X15: Ambiente 2025 exhibitor; joint-stock company (AD) | Y15: Airers & ironing boards are oversize - compare FBM vs FBA | AA15: Trade fair exhibitor listing | AB15: PASS - major trade-fair exhibitor | AC15: Source link | AD15: Search LinkedIn | AE15: Round 5 | AF15: Not contacted | AK15: =IF(AG15="","",WORKDAY(AG15,5))
A16: Croatia | B16: 15 | C16: 3 | D16: Health & Personal Care | E16: Saponia d.d. | F16: C - Low / little UK demand | G16: https://www.saponia.hr | H16: Osijek | J16: EU / Europe | K16: Low-cost | L16: M. Gupca 2, 31000 Osijek | M16: +385 31 513 513 | O16: Manufacturer (listed) | P16: Kalodont toothpaste, Arf, Faks, Ornel, liquid soaps, detergents | Q16: Personal & home care | R16: Pallet / account based | S16: Export to 15+ countries incl. DE, PL, HU, US | T16: Ask | U16: Unknown | V16: Unknown | X16: Listed on Zagreb Stock Exchange; ~EUR 133m revenue (2024); 725 staff | Y16: Toothpaste & soaps: low unit cost; detergents are heavy | AA16: Stock exchange filings + business registry | AB16: PASS - listed company | AC16: Source link | AD16: Search LinkedIn | AE16: Round 5 | AF16: Not contacted | AK16: =IF(AG16="","",WORKDAY(AG16,5))
A17: Czech Republic | B17: 16 | C17: 3 | D17: Beauty | E17: Dermacol a.s. | F17: B - Moderate | G17: https://www.dermacol.cz | H17: Prague | J17: EU / Europe | K17: Low-cost | L17: Vytvarna 1023/4, 161 00 Praha 6 (verify) | O17: Brand owner / manufacturer | P17: Dermacol Make-up Cover, foundations, skincare | Q17: Make-up & skincare | R17: Account based | S17: Regional distributors (60+ countries) | T17: Ask | U17: Unknown | V17: Unknown | X17: Brand since 1966 (Barrandov film studio); Cosmoprof exhibitor; sold via Notino | Y17: Make-up Cover is a known cult product; low Czech prices | Z17: Check the Czech register (ARES) before ordering | AA17: Business press + retailer data | AB17: PASS - major trade-fair exhibitor | AC17: Source link | AD17: Search LinkedIn | AE17: Round 5 | AF17: Not contacted | AK17: =IF(AG17="","",WORKDAY(AG17,5))
A18: Czech Republic | B18: 17 | C18: 3 | D18: Beauty | E18: MANUFAKTURA (Czech cosmetics) | F18: C - Low / little UK demand | G18: Not confirmed - click to search | H18: Prague | J18: EU / Europe | K18: Low-cost | L18: Melantrichova 17, 110 00 Praha 1 | O18: Manufacturer / brand owner | P18: Manufaktura beer, wine & herbal cosmetics, bath salts, gift sets | Q18: Natural cosmetics & gift sets | R18: On request | S18: Head of Sales: David Rožek | T18: Ask | U18: Unknown | V18: Unknown | W18: IČO 49687387 | X18: CzechTrade listing; IČO 49687387; 250+ staff; own shop chain since 1991 | Y18: Gift sets do well in Q4 | AA18: Government export directory | AB18: PASS - government export agency / trade body listing | AC18: Source link | AD18: Search LinkedIn | AE18: Round 5 | AF18: Not contacted | AK18: =IF(AG18="","",WORKDAY(AG18,5))
A19: Czech Republic | B19: 18 | C19: 4 | D19: DIY & Tools | E19: HECHT MOTORS s.r.o. | F19: C - Low / little UK demand | G19: https://en.hecht.cz | H19: Prague | J19: EU / Europe | K19: Low-cost | L19: Prague 4, Czech Republic (see website) | N19: export@hecht.cz | O19: Brand owner / importer-distributor | P19: HECHT lawn mowers, trimmers, chainsaws, pressure washers, workshop tools, e-scooters | Q19: Garden machinery & power tools | R19: On request (export price list) | S19: Export dealers; subsidiaries in SK, PL, HU; ~600 staff | T19: Ask - actively expanding export | U19: Unknown | V19: Unknown | X19: Brand owner since 1994; largest CZ/SK garden & power-products supplier; publishes English export catalogues | Y19: Battery garden tools & pressure washers sell well; petrol items are hazmat; need UK plugs | Z19: Products largely made in Asia under the Hecht brand - check CE/UKCA documents | AA19: Company export catalogues + company site | AB19: PASS - established brand / group | AC19: Source link | AD19: Search LinkedIn | AE19: Round 5 | AF19: Not contacted | AK19: =IF(AG19="","",WORKDAY(AG19,5))
A20: Czech Republic | B20: 19 | C20: 4 | D20: DIY & Tools | E20: NAREX s.r.o. | F20: C - Low / little UK demand | G20: https://www.narex.cz | H20: Česká Lípa | J20: EU / Europe | K20: Low-cost | L20: Chelčického 1932, 470 01 Česká Lípa | M20: +420 481 645 183 | N20: narex@narex.cz | O20: Manufacturer / brand owner | P20: Narex power tools (drills, grinders, saws); Narex Bystřice chisels & woodworking tools | Q20: Power tools & woodworking | R20: Dealer account | S20: Sales partners; commercial terms via sales team | T20: Ask - Narex chisels already sold in UK | U20: Unknown | V20: Unknown | X20: Official company contacts page; long-established Czech tool maker | Y20: Narex chisels have a strong UK woodworking following at lower prices than UK brands | Z20: Power tools need UK plugs / UKCA | AA20: Official company website | AB20: PASS - established brand / group | AC20: Source link | AD20: Search LinkedIn | AE20: Round 5 | AF20: Not contacted | AK20: =IF(AG20="","",WORKDAY(AG20,5))
A21: Czech Republic | B21: 20 | C21: 3 | D21: DIY & Tools | E21: PILANA Metal spol. s r.o. | F21: C - Low / little UK demand | G21: http://www.pilanametal.cz | H21: Hulín | J21: EU / Europe | K21: Low-cost | L21: Nádražní 804, 768 24 Hulín | O21: Manufacturer | P21: Pilana hacksaw blades, band saw blades, small saws & hand cutting tools | Q21: Saw blades & cutting tools | R21: On request | S21: Sales managers: Jiří Mizera, Marek Stratil; ships to 60+ countries | T21: Ask | U21: Unknown | V21: Unknown | W21: IČO 25328956 | X21: CzechTrade listing; IČO 25328956; cutting-tool tradition since 1934 | Y21: Hacksaw blade multipacks - cheap, light consumables | AA21: Government export directory | AB21: PASS - government export agency / trade body listing | AC21: Source link | AD21: Search LinkedIn | AE21: Round 5 | AF21: Not contacted | AK21: =IF(AG21="","",WORKDAY(AG21,5))
A22: Czech Republic | B22: 21 | C22: 4 | D22: Fragrance | E22: BJUTIP a.s. | F22: A - Strong (household name) | G22: https://www.bjutip.com | H22: Brno - Modřice | J22: EU / Europe | K22: Low-cost | L22: Tyršova 1182, 664 42 Brno - Modřice (visit: Vintrovna 395/25, Popůvky 664 41) | M22: +420 724 076 367 | N22: sales@bjutip.com (wholesale); info@bjutip.com | O22: Distributor | P22: Armaf, Afnan, Lattafa, Paris Corner, French Avenue, Khadlaj, Maison Asrar + others | Q22: Arabian / niche fragrance | R22: Min. order value €1,000 | S22: B2B registration on website | T22: Check - EU based (post-Brexit customs apply) | U22: Unknown | V22: Unknown | X22: Registered Regional Court Brno, B 8541; dedicated e-commerce seller programme | Y22: Has an e-commerce seller programme - Arabian brands popular & often easier to list on Amazon | Z22: Strong fit for Lattafa/Armaf etc. Register at bjutip.com/register. | AA22: Company website (via search) | AB22: CAUTION - Registered (IČO 10865373) but young (2021) and sells heavily-counterfeited Arabian brands - ask for brand authorisation letters. | AC22: Source link | AD22: Search LinkedIn | AE22: Round 1 | AF22: Not contacted | AK22: =IF(AG22="","",WORKDAY(AG22,5))
A23: Czech Republic | B23: 22 | C23: 4 | D23: Health & Personal Care | E23: NUTREND D.S., a.s. | F23: C - Low / little UK demand | G23: https://www.nutrend-supplements.com | H23: Olomouc | J23: EU / Europe | K23: Low-cost | L23: Chválkovice 604, 779 00 Olomouc | M23: +420 583 842 592 | N23: export@nutrend.eu | O23: Brand owner / manufacturer | P23: Nutrend sports nutrition, bars, supplements | Q23: Sports nutrition | R23: On request | S23: Distributors (export dept.) | T23: Exports to 60-74 countries - ask | U23: Unknown | V23: Unknown | X23: ~52% exported; record CZK 1.26bn revenue; Gulfood exhibitor | AA23: Catalogue + trade fair + business press | AB23: PASS - major trade-fair exhibitor | AC23: Source link | AD23: Search LinkedIn | AE23: Round 4 | AF23: Not contacted | AK23: =IF(AG23="","",WORKDAY(AG23,5))
A24: Czech Republic | B24: 23 | C24: 4 | D24: Health & Personal Care | E24: SPOKAR a.s. | F24: C - Low / little UK demand | G24: http://www.spokar.com | H24: Pelhřimov | J24: EU / Europe | K24: Low-cost | L24: Libkovodská 1428, 393 01 Pelhřimov | O24: Manufacturer | P24: Spokar toothbrushes, interdental brushes, household & paint brushes | Q24: Oral care & brushes | R24: On request | S24: Key Account Manager: Jan Canek; exports to DE, DK, NO, US, MX | T24: Ask | U24: Unknown | V24: Unknown | W24: IČO 25183427 | X24: CzechTrade listing; IČO 25183427; producing since 1882 | Y24: Toothbrush multipacks & cleaning brushes - low cost, repeat buys; private label possible | AA24: Government export directory | AB24: PASS - government export agency / trade body listing | AC24: Source link | AD24: Search LinkedIn | AE24: Round 5 | AF24: Not contacted | AK24: =IF(AG24="","",WORKDAY(AG24,5))
A25: Czech Republic | B25: 24 | C25: 3 | D25: Health & Personal Care | E25: ALPA, a.s. | F25: C - Low / little UK demand | G25: Not confirmed - click to search | H25: Velké Meziříčí | J25: EU / Europe | K25: Low-cost | L25: Hornoměstská 378/74, 594 01 Velké Meziříčí | M25: +420 566 521 401 (switchboard) | O25: Manufacturer / brand owner | P25: Alpa Francovka (herbal rub), Pedik foot care, Alpa kids cosmetics | Q25: Herbal body care & kids toiletries | R25: On request | S25: Business manager: Ing. Pavel Smažil | T25: Ask - sold on Notino UK | U25: Unknown | V25: Unknown | W25: IČO 27666468 / DIČ CZ27666468 | X25: CzechTrade listing; IČO 27666468; Francovka trademark since 1913 | Y25: Niche herbal products; little UK competition | Z25: Liquids with alcohol - check hazmat | AA25: Government export directory | AB25: PASS - government export agency / trade body listing | AC25: Source link | AD25: Search LinkedIn | AE25: Round 5 | AF25: Not contacted | AK25: =IF(AG25="","",WORKDAY(AG25,5))
A26: Czech Republic | B26: 25 | C26: 4 | D26: Home & Kitchen | E26: Tescoma s.r.o. (export centre Tescoma S.p.A., Italy) | F26: B - Moderate | G26: https://www.tescoma.cz | H26: Zlín (HQ); export centre Brescia, Italy | J26: EU / Europe | K26: Low-cost | L26: U Tescomy 241, 760 01 Zlín / Export: Via Traversa Caduti del Lavoro 3, 25046 Cazzago San Martino (IT) | M26: +39 030 775 1394 (export centre) | O26: Brand owner / manufacturer | P26: Tescoma kitchen utensils, cookware, baking, storage (thousands of SKUs) | Q26: Kitchenware | R26: On request | S26: Distributors & retailers | T26: Sold in 100-130 countries - ask | U26: Unknown | V26: Unknown | X26: Ambiente exhibitor; branches in IT, ES, PT, SK, PL, DE, CN | Y26: Kitchen gadgets largely ungated - brand-direct invoices | Z26: Use the Italian export centre for foreign accounts. | AA26: Trade fair profile + Wikipedia | AB26: PASS - major trade-fair exhibitor | AC26: Source link | AD26: Search LinkedIn | AE26: Round 4 | AF26: Not contacted | AK26: =IF(AG26="","",WORKDAY(AG26,5))
A27: Czech Republic | B27: 26 | C27: 3 | D27: Home & Kitchen | E27: Remoska s.r.o. | F27: B - Moderate | G27: Not confirmed - click to search | H27: Kopřivnice (Vlčovice) | J27: EU / Europe | K27: Low-cost | L27: Průmyslový park 303, Vlčovice, 742 21 Kopřivnice | O27: Manufacturer | P27: Remoska portable electric ovens, pans | Q27: Small cooking appliances | R27: On request | S27: ~40% exported, half of that to the UK | T27: Yes - already strong UK market | U27: Unknown | V27: Unknown | W27: IČO 01885219 | X27: CzechTrade listing; IČO 01885219; brand since 1957; Forbes CZ coverage | Y27: Remoska has a UK following - check existing UK distributor exclusivity | Z27: UK may have an exclusive distributor | AA27: Government export directory + business press | AB27: PASS - government export agency / trade body listing | AC27: Source link | AD27: Search LinkedIn | AE27: Round 5 | AF27: Not contacted | AK27: =IF(AG27="","",WORKDAY(AG27,5))
A28: Czech Republic | B28: 27 | C28: 4 | D28: Home & Kitchen | E28: PLASTIA s.r.o. (Urbalive) | F28: C - Low / little UK demand | G28: https://www.plastia.cz | H28: Nové Veselí (Vysočina) | J28: EU / Europe | K28: Low-cost | L28: Žďárská 313, 592 14 Nové Veselí | M28: +420 566 667 001 | N28: info@plastia.cz | O28: Manufacturer (family-owned) | P28: Plastia self-watering planters, Urbalive (incl. pet products) | Q28: Planters & home-garden | R28: On request | S28: Distributors in 56+ countries | T28: Ask | U28: Unknown | V28: Unknown | X28: CzechTrade listing; Spoga+Gafa, IPM Essen & Interzoo exhibitor | Y28: Self-watering pots & herb planters sell well; light and stackable | AA28: Government export directory + 3 trade fairs | AB28: PASS - government export agency / trade body listing | AC28: Source link | AD28: Search LinkedIn | AE28: Round 5 | AF28: Not contacted | AK28: =IF(AG28="","",WORKDAY(AG28,5))
A29: Czech Republic | B29: 28 | C29: 3 | D29: Home & Kitchen | E29: BLEX, a.s. | F29: C - Low / little UK demand | G29: Not confirmed - click to search | H29: Karlovy Vary | J29: EU / Europe | K29: Low-cost | L29: Závodu míru 327/4, 360 17 Karlovy Vary | O29: Manufacturer | P29: Tinplate & non-stick bakeware, wire kitchenware | Q29: Bakeware | R29: On request | S29: Export buyers (export manager: Kateřina Veselá) | T29: Ask - exports worldwide | U29: Unknown | V29: Unknown | W29: IČO 25247409 | X29: Listed in the CzechTrade (government agency) exporter directory | Y29: Baking tins & moulds are a steady category; possible private label | AA29: Government export directory | AB29: PASS - government export agency / trade body listing | AC29: Source link | AD29: Search LinkedIn | AE29: Round 4 | AF29: Not contacted | AK29: =IF(AG29="","",WORKDAY(AG29,5))
A30: Czech Republic | B30: 29 | C30: 3 | D30: Home & Kitchen | E30: Dřevotvar družstvo | F30: C - Low / little UK demand | G30: https://www.drevotvar.cz | H30: Jablonné nad Orlicí | J30: EU / Europe | K30: Low-cost | L30: Slezská 535, 561 64 Jablonné nad Orlicí | M30: +420 465 677 111 (sales: +420 465 677 219) | N30: drevotvar@drevotvar.cz | O30: Manufacturer (cooperative) | P30: Wooden kitchen utensils & boards | Q30: Wooden kitchenware | R30: On request | S30: Export buyers (85% of output exported) | T30: Ask | U30: Unknown | V30: Unknown | W30: IČO 00029882 | X30: Listed in the CzechTrade exporter directory | Y30: Wooden utensils & chopping boards - possible private label | AA30: Government export directory | AB30: PASS - government export agency / trade body listing | AC30: Source link | AD30: Search LinkedIn | AE30: Round 4 | AF30: Not contacted | AK30: =IF(AG30="","",WORKDAY(AG30,5))
A31: Czech Republic | B31: 30 | C31: 3 | D31: Pet Supplies | E31: Funky Dog (Czech eco pet accessories) | F31: C - Low / little UK demand | G31: Not confirmed - click to search | H31: Prague | J31: EU / Europe | K31: Low-cost | L31: Braunerova 7, 180 00 Praha | O31: Manufacturer / brand owner | P31: Funky Dog vegan collars, leads, beds | Q31: Eco pet accessories | R31: On request | S31: Distributors (SK, AT, IT, SI); CEO Katarína Králová | T31: Ask | U31: Unknown | V31: Unknown | W31: IČO 03688623 | X31: CzechTrade listing; IČO 03688623; since 2015 | Y31: Eco/vegan collars are a growing niche | Z31: Small firm - check capacity | AA31: Government export directory | AB31: PASS - government export agency / trade body listing | AC31: Source link | AD31: Search LinkedIn | AE31: Round 5 | AF31: Not contacted | AK31: =IF(AG31="","",WORKDAY(AG31,5))
A32: Czech Republic | B32: 31 | C32: 3 | D32: Pet Supplies | E32: Tommi CZ s.r.o. (Tommiland B2B) | F32: C - Low / little UK demand | G32: http://www.tommicz.eu | H32: Písek | J32: EU / Europe | K32: Low-cost | L32: Za Nádražím 2569, 397 01 Písek | M32: +420 382 264 269 | O32: Manufacturer / distributor | P32: Asan, Cat Step, Dr. Jag, Catwill, Doggies + European brands - 3,500+ products | Q32: Pet care & litter | R32: Min. order value ~€1,000 (2018 - confirm) | S32: Registered partners only (B2B e-shop) | T32: Exports - ask | U32: Unknown | V32: Unknown | X32: Founded 1989; CzechTrade exporter; export manager Hana Bečková | AA32: Trade show + CzechTrade directory | AB32: PASS - government export agency / trade body listing | AC32: Source link | AD32: Search LinkedIn | AE32: Round 2 | AF32: Not contacted | AK32: =IF(AG32="","",WORKDAY(AG32,5))
A33: Czech Republic | B33: 32 | C33: 4 | D33: Sports & Outdoors | E33: GALA a.s. | F33: C - Low / little UK demand | G33: https://www.gala.cz | H33: Prostějov | J33: EU / Europe | K33: Low-cost | L33: Západní 1/75, 796 04 Prostějov | M33: +420 739 648 045 | N33: grmelova@gala.cz (sales manager) | O33: Manufacturer | P33: Gala volleyballs, basketballs, footballs, handballs | Q33: Sports balls | R33: On request | S33: Sales manager Alena Grmelová | T33: Ask | U33: Unknown | V33: Unknown | W33: IČO 49969820 | X33: FIBA equipment partner; IČO 49969820; published annual reports | Y33: Volleyballs & beach balls sell well in summer; low cost vs Mikasa/Molten | AA33: FIBA partner listing + company register | AB33: PASS - company register entry | AC33: Source link | AD33: Search LinkedIn | AE33: Round 5 | AF33: Not contacted | AK33: =IF(AG33="","",WORKDAY(AG33,5))
A34: Czech Republic | B34: 33 | C34: 4 | D34: Sports & Outdoors | E34: Plastkon product s.r.o. (Gizmo Riders) | F34: C - Low / little UK demand | G34: http://www.plastkon.cz | H34: Mikulovice | J34: EU / Europe | K34: Low-cost | L34: Hlavní 147, 790 84 Mikulovice | O34: Manufacturer | P34: Gizmo Riders & Snowflake sledges, snow shovels; Gardenico & Flower Lover garden products | Q34: Sledges, winter & garden plastics | R34: On request | S34: Exports to 70+ countries | T34: Ask | U34: Unknown | V34: Unknown | W34: IČO 63321289 | X34: CzechTrade listing; IČO 63321289; since 1998; ~195 staff | Y34: Sledges sell strongly Nov-Jan in UK (snow years); plant pots in spring | Z34: Very seasonal - order early | AA34: Government export directory + company site | AB34: PASS - government export agency / trade body listing | AC34: Source link | AD34: Search LinkedIn | AE34: Round 5 | AF34: Not contacted | AK34: =IF(AG34="","",WORKDAY(AG34,5))
A35: Czech Republic | B35: 34 | C35: 3 | D35: Sports & Outdoors | E35: BP Lumen s.r.o. | F35: C - Low / little UK demand | G35: Not confirmed - click to search | H35: Úpice | J35: EU / Europe | K35: Low-cost | L35: Puškinova 546, 542 32 Úpice | O35: Manufacturer + parts wholesaler | P35: Levit & Qayron bikes/e-bikes; wholesale bicycle parts & accessories; private-label assembly | Q35: Bicycle parts & accessories wholesale | R35: On request | S35: Exports to 20+ European countries | T35: Ask | U35: Unknown | V35: Unknown | W35: IČO 05565375 | X35: CzechTrade listing; IČO 05565375; trading since 1991; 51-250 staff | Y35: Bike parts/accessories wholesale (tubes, tyres, lights) - small items suit FBA | Z35: E-bikes have lithium batteries (hazmat) | AA35: Government export directory | AB35: PASS - government export agency / trade body listing | AC35: Source link | AD35: Search LinkedIn | AE35: Round 5 | AF35: Not contacted | AK35: =IF(AG35="","",WORKDAY(AG35,5))
A36: Czech Republic | B36: 35 | C36: 3 | D36: Sports & Outdoors | E36: Sedco s.r.o. | F36: C - Low / little UK demand | G36: Not confirmed - click to search | H36: Prostějov | J36: EU / Europe | K36: Low-cost | L36: Průmyslová 3143/5, 796 01 Prostějov | N36: obchod@sedco.cz | O36: Wholesaler / importer + own brand | P36: Sedco sports & recreation equipment (balls, fitness, rackets, outdoor games) | Q36: Sports & recreation wholesale | R36: Trade account | S36: Wholesale customers; sells on Decathlon marketplace | T36: Ask | U36: Unknown | V36: Unknown | X36: Registered 2000 (EMIS); own warehouse complex in Prostějov; Decathlon marketplace seller (CZ & PL) | Y36: Cheap fitness & garden-game items; check own-brand vs third-party lines | AA36: Marketplace seller data + business database | AB36: PASS - company register entry | AC36: Source link | AD36: Search LinkedIn | AE36: Round 5 | AF36: Not contacted | AK36: =IF(AG36="","",WORKDAY(AG36,5))
A37: Czech Republic | B37: 36 | C37: 4 | D37: Stationery & Office | E37: KOH-I-NOOR HARDTMUTH a.s. | F37: B - Moderate | G37: https://www.koh-i-noor.cz | H37: České Budějovice | J37: EU / Europe | K37: Low-cost | L37: F. A. Gerstnera 21/3, 370 01 České Budějovice | N37: kht@koh-i-noor.cz | O37: Brand owner / manufacturer | P37: Koh-i-noor pencils, crayons, art supplies, Progresso | Q37: Art & school supplies | R37: On request | S37: Distributors & retailers (trade arm in Pelhřimov) | T37: Exports to 90+ countries - ask | U37: Unknown | V37: Unknown | X37: Historic Czech manufacturer; factories in CZ & BG | Y37: Art supplies sell well | AA37: Wikipedia + retailer imprint + registry | AB37: PASS - company register entry | AC37: Source link | AD37: Search LinkedIn | AE37: Round 4 | AF37: Not contacted | AK37: =IF(AG37="","",WORKDAY(AG37,5))
A38: Czech Republic | B38: 37 | C38: 4 | D38: Toys & Games | E38: Dino Toys s.r.o. | F38: C - Low / little UK demand | G38: https://www.dinotoys.cz | H38: Mnichovo Hradiště | J38: EU / Europe | K38: Low-cost | L38: K Pískovně 108, 295 01 Mnichovo Hradiště | M38: +420 324 709 315 (verify) | N38: export@dinotoys.cz | O38: Manufacturer | P38: Dino puzzles, board games, cards; Disney & Krtek (Little Mole) licences | Q38: Puzzles & board games | R38: On request | S38: Export manager: Barbora Kovaříková; exports to 20+ countries | T38: Ask | U38: Unknown | V38: Unknown | W38: IČO 49101650 | X38: CzechTrade (government export agency) listing; IČO 49101650; since 1993 | Y38: Puzzles are made in CZ at low cost - good margin potential; check licence rules for Disney lines | AA38: Government export directory + retailer data | AB38: PASS - government export agency / trade body listing | AC38: Source link | AD38: Search LinkedIn | AE38: Round 5 | AF38: Not contacted | AK38: =IF(AG38="","",WORKDAY(AG38,5))
A39: Czech Republic | B39: 38 | C39: 3 | D39: Toys & Games | E39: Albi Česká republika a.s. | F39: C - Low / little UK demand | G39: https://www.albi.cz | H39: Červený Kostelec (warehouse) | J39: EU / Europe | K39: Low-cost | L39: Lhota za Červeným Kostelcem 439 (warehouse) | O39: Publisher / distributor / retailer | P39: Albi board games, gifts, Kouzelné čtení; distributes partner publishers | Q39: Board games & gifts | R39: On request | S39: Bookshops, toy stores, hypermarkets | T39: CZ/SK/PL focus - ask | U39: Unknown | V39: Unknown | X39: Czech business award winner; own shop chain; Ares Games EU distribution partner | AA39: Business press + job listings | AB39: PASS - well-known company: Leading Czech games publisher & retailer. | AC39: Source link | AD39: Search LinkedIn | AE39: Round 4 | AF39: Not contacted | AK39: =IF(AG39="","",WORKDAY(AG39,5))
A40: Czech Republic | B40: 39 | C40: 3 | D40: Toys & Games | E40: Bino Europe k.s. | F40: C - Low / little UK demand | G40: Not confirmed - click to search | H40: Mladá Boleslav | J40: EU / Europe | K40: Low-cost | L40: tř. Václava Klementa 836, 293 01 Mladá Boleslav | O40: Manufacturer / distributor | P40: Bino wooden & plastic toys, children's furniture, nursery equipment | Q40: Toddler & wooden toys | R40: On request | S40: Exports to 30+ countries; offices in China & Germany | T40: Ask | U40: Unknown | V40: Unknown | W40: IČO 24220931 / VAT CZ24220931 | X40: CzechTrade listing; IČO 24220931; VAT CZ24220931; LEI 3157004KB9Y233461R58 | Y40: Cheap wooden/toddler toys; ask for EN71 reports (some made in China) | Z40: Some products made in China - check origin & compliance | AA40: Government export directory + company register | AB40: PASS - government export agency / trade body listing | AC40: Source link | AD40: Search LinkedIn | AE40: Round 5 | AF40: Not contacted | AK40: =IF(AG40="","",WORKDAY(AG40,5))
...

Sheet Low Priority
A1: Low Priority suppliers (priority 1-2) - reference only
A2: 42 suppliers moved off the main Suppliers tab: weak Amazon fit, marketplaces/retailers, or capped after the scam check. Work the main list first; vet these carefully before paying.
A4: Country | B4: Category | C4: Priority | D4: Company | E4: Website | F4: Phone | G4: Email | H4: Supplier Type | I4: Key Brands | J4: Why low priority / notes | K4: Scam Check | L4: Source
A5: Austria | B5: Sports & Outdoors | C5: 2 | D5: SWAROVSKI OPTIK Vertriebs GmbH | E5: https://www.swarovskioptik.com | F5: +43 5223 511-0 | G5: info@swarovskioptik.com | H5: Brand owner / manufacturer | I5: Swarovski Optik binoculars, scopes | J5: Selective distribution - Amazon resale may be restricted; High-ticket, low volume; brand control is strict | K5: PASS - established brand / group | L5: https://swarovskioptik.com/ch/en/hunting/about-us/quality-and-innovation/facts-and-figures
A6: Belgium | B6: Beauty | C6: 2 | D6: Euro Cosmetic | E6: https://www.eurocosmetic.be | F6: +32 472 ... (see website) | H6: Distributor / wholesaler | I6: Cosmetic brands (salons & retailers) | K6: CAUTION - Likely Eurocosmetics & Accessoires BVBA (BE0479.392.014) - confirm before ordering. | L6: https://oncosmetics.com/company/eurocosmetic-international/
A7: Bulgaria | B7: Baby Products | C7: 2 | D7: Iventas | E7: https://bulmedica.bg/en/main/iventas-2/ | H7: Importer / national distributor | I7: Philips AVENT, Philips Sonicare, Tommee Tippee + others | K7: CAUTION - Details only from its own page - verify in the Bulgarian Commercial Register. | L7: https://bulmedica.bg/en/main/iventas-2/
A8: Czech Republic | B8: Pet Supplies | C8: 2 | D8: Samohýl Group | E8: https://samohyl.cz/?lang=en | H8: Wholesaler / exclusive distributor | I8: Exclusive CZ distributor for ~20 brands incl. KONG | K8: PASS (checked) - Listed among Forbes Czech's largest family firms (2026); vet wholesaler since 1991. | L8: https://samohyl.cz/?lang=en
A9: Czech Republic | B9: Toys & Games | C9: 2 | D9: Teddies s.r.o. | H9: Toy importer / wholesaler | I9: Teddies plush & toys range (sold via Alza etc.) | K9: PASS (checked) - Registered (IČ 28268164); no insolvency found. | L9: https://www.emis.cn/php/company-profile/CZ/Teddies_SRO_en_6714203.html
A10: France | B10: B2B Marketplace | C10: 2 | D10: Ankorstore | E10: https://www.ankorstore.com | H10: Wholesale marketplace (independent brands) | I10: ~30,000 independent brands - beauty, toys, gifts, home | J10: 60-day payment terms.; CAUTION: many brands prohibit marketplace resale - check each brand | K10: PASS - well-known company: Major VC-backed European wholesale marketplace. | L10: https://alven.co/news/ankorstore-reaches-unicorn-status-in-only-two-years-with-its-last-e250-million-series-c-funding-round
