Workbook

Sheet Summary
A1: EU Perfume & Aftershave Wholesale Suppliers - Outreach List
A2: Compiled Oct 2026 from public web sources. Websites marked 'From directory - verify' came from business directories; open them to confirm before outreach.
A4: Metric | B4: Count
A5: Total EU suppliers | B5: =COUNT('EU Suppliers'!A2:A79) -> 66
A6: With a website | B6: =COUNTIF('EU Suppliers'!E2:E79,"http*") -> 55
A7: No website found | B7: =COUNTIF('EU Suppliers'!E2:E79,"Not found") -> 11
A8: High priority | B8: =COUNTIF('EU Suppliers'!N2:N79,"High") -> 20
A9: Medium priority | B9: =COUNTIF('EU Suppliers'!N2:N79,"Medium") -> 27
A10: Low priority / caution | B10: =COUNTIF('EU Suppliers'!N2:N79,"Low") -> 19
A11: With a direct email listed | B11: =COUNTIF('EU Suppliers'!H2:H79,"*@*.*") -> 9
A12: Contacted so far | B12: =COUNTA('EU Suppliers'!Q2:Q79)-COUNTIF('EU Suppliers'!Q2:Q79,"Not contacted") -> 0
A13: Accounts opened | B13: =COUNTIF('EU Suppliers'!Q2:Q79,"Account opened") -> 0
A15: Suppliers by country
A16: Country | B16: Suppliers
A17: Austria | B17: =COUNTIF('EU Suppliers'!C2:C79,A17) -> 1
A18: Belgium | B18: =COUNTIF('EU Suppliers'!C2:C79,A18) -> 5
A19: Bulgaria | B19: =COUNTIF('EU Suppliers'!C2:C79,A19) -> 3
A20: Czech Republic | B20: =COUNTIF('EU Suppliers'!C2:C79,A20) -> 3
A21: France | B21: =COUNTIF('EU Suppliers'!C2:C79,A21) -> 7
A22: Germany | B22: =COUNTIF('EU Suppliers'!C2:C79,A22) -> 6
A23: Greece | B23: =COUNTIF('EU Suppliers'!C2:C79,A23) -> 1
A24: Hungary | B24: =COUNTIF('EU Suppliers'!C2:C79,A24) -> 1
A25: Italy | B25: =COUNTIF('EU Suppliers'!C2:C79,A25) -> 7
A26: Lithuania | B26: =COUNTIF('EU Suppliers'!C2:C79,A26) -> 1
A27: Netherlands | B27: =COUNTIF('EU Suppliers'!C2:C79,A27) -> 9
A28: Poland | B28: =COUNTIF('EU Suppliers'!C2:C79,A28) -> 6
A29: Romania | B29: =COUNTIF('EU Suppliers'!C2:C79,A29) -> 3
A30: Spain | B30: =COUNTIF('EU Suppliers'!C2:C79,A30) -> 12
A31: Sweden | B31: =COUNTIF('EU Suppliers'!C2:C79,A31) -> 1
A33: HOW TO USE
A34: - The supplier list is grouped into numbered sections: marketplaces first, then by country, then leads with no website found.
A35: - Website = company homepage. 'Wholesale Sign-up / Contact Page' = the best page to start outreach from.
A36: - Priority: High = designer/branded focus, clear B2B terms or official distributor; Medium = relevant but unverified; Low = directory-only, mainly retail, or a risk flag.
A37: - Yellow columns are yours to fill in. Outreach Status has a drop-down.
A38: AMAZON-SPECIFIC CHECKS BEFORE BUYING
A39: - Ask for a sample invoice: supplier's full name, address and VAT number; your business name/address; product names + quantities.
A40: - Fragrance ungating usually needs distributor/manufacturer invoices (often 10+ units, last 180 days). Ask if their invoices have passed ungating before.
A41: - Ask for a Letter of Authorisation or chain-of-supply proof for restricted / brand-registered lines.
A42: - Avoid 'equivalents', 'dupes', 'testers' and unrealistically cheap designer stock (e.g. under EUR 5 a bottle).
A43: - Check VAT numbers on VIES and the company on its national registry (KvK, Handelsregister, Pappers, KRS, ARES) before paying.

Sheet EU Suppliers
A1: # | B1: Company | C1: Country | D1: City / Region | E1: Website | F1: Website Check | G1: Wholesale Sign-up / Contact Page | H1: Email | I1: Phone | J1: Address | K1: Supplier Type | L1: Brands / Focus | M1: MOQ / Terms | N1: Priority | O1: Notes / Risk Flags | P1: Source (where found) | Q1: Outreach Status | R1: Date Contacted | S1: Follow-up Date | T1: Response / Notes
A2: 1. B2B MARKETPLACES & WHOLESALE PLATFORMS (EU-wide) (3)
A3: 1 | B3: Qogita | C3: Netherlands | D3: Amsterdam | E3: https://www.qogita.com | F3: Confirmed | G3: https://www.qogita.com | H3: Via help centre / chat after sign-up | J3: Amsterdam | K3: B2B wholesale marketplace (500+ vetted distributors) | L3: Health, beauty & fragrance - big designer brands; GTIN-based catalogue | M3: Low MOQ; invoices supplied for 3rd-party resellers | N3: High | O3: Popular with Amazon sellers. Check per-brand ungating acceptance. | P3: https://www.qogita.com/brands/lamour/ | Q3: Not contacted
A4: 2 | B4: Nova Engel | C4: Spain | D4: Palma de Mallorca (logistics Madrid) | E4: https://www.novaengel.com | F4: Confirmed | G4: https://www.novaengel.com/en/company_wholesaler_perfumery | H4: Via website contact form | I4: +34 971 75 67 27 / 902 999 169 | J4: C/ Asipo 4, 07011 Palma de Mallorca | K4: Perfumery wholesaler + dropship/crossdock | L4: Large branded perfume & cosmetics catalogue; API for wholesale & dropship | M4: Professional buyers only | N4: High | O4: 75+ years trading. | P4: https://www.novaengel.com/en/company_wholesaler_perfumery | Q4: Not contacted
A5: 3 | B5: BigBuy | C5: Spain | D5: Aldaia (Valencia) | E5: https://www.bigbuy.eu | F5: Confirmed | G5: https://www.bigbuy.eu | H5: Via website | J5: Aldaia, Valencia | K5: B2B wholesale / dropship platform | L5: Multi-category incl. perfume & cosmetics | M5: Subscription (~EUR 69-99/month + setup) - verify | N5: Medium | O5: Easy start; higher prices than specialists. | P5: https://help.wizishop.com/hc/en-us/articles/360015881879-Presentation-of-BigBuy | Q5: Not contacted
A6: 2. NETHERLANDS (7)
A7: 4 | B7: Beautinow | C7: Netherlands | D7: NL warehouse | E7: https://beautinow.com | F7: Confirmed | G7: https://beautinow.com/wholesale-perfume-supplier-europe/ | H7: Not public - use website contact page | J7: Netherlands | K7: Perfume wholesaler & dropship | L7: 2,000+ fragrances, niche & designer | M7: Enquire by email; account manager replies in 1 working day | N7: High | O7: Claims 100% original stock. | P7: https://beautinow.com/wholesale-perfume-supplier-europe/ | Q7: Not contacted
A8: 5 | B8: AH Beauté BV | C8: Netherlands | D8: Utrecht (warehouses Rotterdam & Antwerp) | E8: https://www.beautetrade.com/suppliers/ah-beauty-bv-107939/ | F8: Beautetrade profile only | G8: https://www.beautetrade.com/suppliers/ah-beauty-bv-107939/ | H8: Via Beautetrade 'contact supplier' | J8: Utrecht | K8: Wholesaler (est. 2014) | L8: Branded perfumes, aftershaves, skincare, make-up | M8: Full or partial orders, break-bulk | N8: High | O8: Exactly matches perfume + aftershave brief. | P8: https://www.beautetrade.com/suppliers/ah-beauty-bv-107939/ | Q8: Not contacted
A9: 6 | B9: EleganceWholesale | C9: Netherlands | E9: https://elegancewholesale.co.nl | F9: Confirmed | G9: https://elegancewholesale.co.nl/partner-with-us | H9: Not public - use website contact page | J9: Netherlands | K9: Wholesaler (B2B only) | L9: Luxury perfumes, cosmetics, designer clothing | M9: Verified businesses only; partner form | N9: Medium | O9: Disclaimer says 'EleganceTrading' - check KvK. | P9: https://elegancewholesale.co.nl/our-services | Q9: Not contacted
A10: 7 | B10: Tradefor7 | C10: Netherlands | D10: Zoetermeer | E10: https://tradefor7.com | F10: From directory - verify | G10: https://tradefor7.com | H10: Not public - use website contact page | J10: Zoetermeer | K10: Wholesaler / distributor | L10: Lattafa, French Avenue, Volare, Swiss Arabian | M10: Min EUR 350 ex VAT; min 6 pcs per fragrance | N10: Medium | O10: Fast-moving Arabian brands. | P10: https://www.marktplaats.nl/v/sieraden-tassen-en-uiterlijk/uiterlijk-parfum/m2420639384-volare-french-avenue-swiss-arabian-lattafa-groothandel | Q10: Not contacted
A11: 8 | B11: Stock Perfume | C11: Netherlands | D11: Utrecht | E11: https://stockperfume.com | F11: Confirmed | G11: https://stockperfume.com | H11: Not public - use website contact page | J11: Utrecht | K11: Perfume wholesaler | L11: Branded perfumes | M11: Min order EUR 500 (page may be dated) | N11: Medium | O11: Confirm still trading. | P11: https://oncosmetics.com/company/stock-perfume/ | Q11: Not contacted
A12: 9 | B12: Join Stadskanaal B.V. | C12: Netherlands | D12: Stadskanaal | E12: https://www.beautetrade.com/products/global-wholesale-distributor-of-cosmetics-skincare-fragrances/75837 | F12: Beautetrade profile only | G12: https://www.beautetrade.com/products/global-wholesale-distributor-of-cosmetics-skincare-fragrances/75837 | H12: Via Beautetrade 'contact supplier' | J12: Stadskanaal | K12: Global wholesale distributor | L12: Cosmetics, skincare, fragrances | N12: Medium | O12: Ask for brand list. | P12: https://www.beautetrade.com/products/global-wholesale-distributor-of-cosmetics-skincare-fragrances/75837 | Q12: Not contacted
A13: 10 | B13: La Parfumista | C13: Netherlands | D13: Utrecht | E13: https://laparfumista.com | F13: From directory - verify | G13: https://laparfumista.com | H13: Not public - use website contact page | J13: Floridadreef 100, Utrecht | K13: Distributor + online retail (est. 2010) | L13: Popular & niche perfumes | N13: Low | O13: Mainly retail - ask about trade. | P13: https://oncosmetics.com/company/la-parfumista/ | Q13: Not contacted
A14: 3. BELGIUM (2)
A15: 11 | B15: Beautylux (Desa Beautylux) | C15: Belgium | D15: Brussels (Schaerbeek) | E15: https://www.beautylux.be | F15: From directory - verify | G15: https://www.beautylux.be | H15: @beautylux.be (see website) | I15: +32 2 7.. (see website) | J15: Rue François Bossaerts 47-51, Brussels | K15: Importer & distributor (since 1980) | L15: Benelux brand distributor e.g. Ariana Grande, Bentley; 450+ doors | N15: High | O15: Official brand distributor. | P15: https://oncosmetics.com/company/beautylux/ | Q15: Not contacted
A16: 12 | B16: Fragrance Privée | C16: Belgium | D16: Brussels | E16: https://www.fragrance-privee.com | F16: From directory - verify | G16: https://www.fragrance-privee.com | H16: contact@fragrance-privee.com | I16: +32 4 88 82 50 07 (Michel Delogne) | J16: Brussels 1000/1030 | K16: Branded perfume wholesaler | L16: Big-brand perfumes, '100% authentic' | M16: Conditions on request | N16: High | O16: Named contact - good first call. | P16: https://www.destockplus.com/acheter/recherche-fournisseur-2-parfumerie.html | Q16: Not contacted
A17: 4. GERMANY (5)
A18: 13 | B18: Alexander Frank - Perfume-Trading.com | C18: Germany | D18: Rangsdorf | E18: https://perfume-trading.com | F18: From directory - verify | G18: https://perfume-trading.com | H18: Not public - use website contact page | J18: Rangsdorf | K18: Wholesale & trading company | L18: Perfumes, fragrances, skin & hair care | N18: Medium | O18: Small (1-10 staff). | P18: https://ensun.io/search/perfume-cologne-fragrance/germany | Q18: Not contacted
A19: 14 | B19: Emporium Handels & Vertriebs GmbH (Parfumtrend) | C19: Germany | D19: Rodenbach | E19: https://parfumtrend.com | F19: From directory - verify | G19: https://parfumtrend.com | H19: Not public - use website contact page | J19: Industriestr. 15, Rodenbach | K19: Perfume wholesaler / e-tailer | L19: 1,800+ luxury perfumes in stock, 48h delivery | N19: Medium | O19: Website linked by shared address - confirm via Impressum. | P19: https://oncosmetics.com/company/parfumtrend/ | Q19: Not contacted
A20: 15 | B20: Aroma Company | C20: Germany | D20: Langen (Hessen) | E20: https://aromacompany.de | F20: From directory - verify | G20: https://aromacompany.de | H20: Not public - use website contact page | J20: August-Bebel-Straße 22, Langen | K20: Distributor / wholesaler / retailer (est. 1998) | L20: Fragrances | N20: Low | P20: https://oncosmetics.com/company/aroma-company | Q20: Not contacted
A21: 16 | B21: Brocard Parfums GmbH | C21: Germany | D21: Berlin | E21: https://brocard.com | F21: From directory - verify | G21: https://brocard.com | H21: Not public - use website contact page | J21: Berlin | K21: Exporter / distributor | L21: Distributes 70+ European manufacturers (CIS focus) | N21: Low | O21: Export focus East. | P21: https://oncosmetics.com/company/brocard/ | Q21: Not contacted
A22: 17 | B22: Parfimo GmbH | C22: Germany | D22: Munich | E22: https://www.parfimo.de | F22: From directory - verify | G22: https://www.parfimo.de | H22: klein@parfimo.de | I22: +49 89 20190347 | J22: Stahlgruberring 36, 81829 München | K22: Perfume trader / online shop | L22: Designer perfumes | N22: Low | O22: Mainly consumer shop (ships DE only) - ask about B2B. | P22: https://implisense.com/de/companies/parfimo-gmbh-muenchen-DE5DGBY5YA30 | Q22: Not contacted
A23: 5. FRANCE (6)
A24: 18 | B24: Perfume Europe | C24: France | D24: Paris (warehouse) | E24: https://perfumeeurope.com | F24: Confirmed | G24: https://perfumeeurope.com/en/ | H24: Not public - use website contact page | J24: Paris | K24: Online B2B perfume wholesaler | L24: 1,500+ references, designer brands | M24: Min EUR 200 ex VAT; free EU delivery over EUR 500 | N24: High | O24: EU VAT auto-checked; ex-VAT invoices. | P24: https://perfumeeurope.com/en/ | Q24: Not contacted
A25: 19 | B25: Parfums en Gros | C25: France | D25: Vénissieux (69) | E25: https://parfums-en-gros.com | F25: From directory - verify | G25: https://parfums-en-gros.com | H25: Not public - use website contact page | I25: +33 6 .. (see website) | J25: 30 Rue Léo Lagrange, Vénissieux | K25: Perfume wholesaler (B2B) | L25: Perfumes & fragrances | N25: Medium | P25: https://oncosmetics.com/company/parfums-en-gros/ | Q25: Not contacted
A26: 20 | B26: Europ Cosmetics (Ed. Pinaud Inovital) | C26: France | D26: Torcy (77) | E26: https://www.beautetrade.com/suppliers/europ-cosmetics-209557 | F26: Beautetrade profile only | G26: https://www.beautetrade.com/suppliers/europ-cosmetics-209557 | H26: Via Beautetrade 'contact supplier' | J26: 3 Rue des Épinettes, 77200 Torcy | K26: Trading / wholesale / export | L26: Skincare, haircare, fragrances | N26: Medium | P26: https://www.beautetrade.com/suppliers/europ-cosmetics-209557 | Q26: Not contacted
A27: 21 | B27: Grossmaillot | C27: France | D27: Montfermeil (93) | E27: https://grossmaillot.com | F27: From directory - verify | G27: https://grossmaillot.com | H27: Not public - use website contact page | J27: Montfermeil 93370 | K27: Wholesaler | L27: Branded, niche & oriental perfumes | M27: Bulk pricing on request | N27: Low | O27: Classified-ad lead - verify authenticity. | P27: https://www.destockplus.com/acheter/recherche-fournisseur-2-parfumerie.html | Q27: Not contacted
A28: 22 | B28: Royaume du Parfum International (RPI) | C28: France | D28: Paris 10e | E28: https://royaumeduparfumparis.com | F28: From directory - verify | G28: https://royaumeduparfumparis.com | H28: Not public - use website contact page | J28: Rue Poissonnière, Paris | K28: Wholesaler & retailer (est. 1996) | L28: French-made perfumes (own label) | N28: Low | O28: Mostly own label. | P28: https://oncosmetics.com/company/royaume-du-parfum-international-rpi/ | Q28: Not contacted
A29: 23 | B29: Firoza Distribution SAS | C29: France | D29: Choisy-le-Roi (94) | E29: https://www.firozadistribution.com | F29: From directory - verify | G29: https://www.firozadistribution.com | H29: firozadistribution@hotmail.fr | I29: +33 6 68 89 19 45 (Nicolas) | J29: 4 avenue Danville, 94600 Choisy-le-Roi | K29: Wholesaler with 400 m² showroom | L29: 500+ 'branded' fragrances | M29: Volume pricing | N29: Low | O29: CAUTION: ~EUR 3.50/unit at 1,000 pcs - too cheap for genuine designer stock. | P29: https://www.destockplus.com/acheter/c-813880-firoza-distribution-destockage.html | Q29: Not contacted
A30: 6. SPAIN (10)
A31: 24 | B31: Ocean Fragrances | C31: Spain | D31: Barcelona | E31: https://oceanfragrances.com | F31: From directory - verify | G31: https://oceanfragrances.com/es/ | H31: Via website | I31: +34 682 62 27 67 | J31: La Rambla, 08005 Barcelona | K31: Wholesaler + dropship/crossdock | L31: 500+ brands, 10,000+ SKUs: Dior, Lancôme, YSL, Guerlain, Paco Rabanne | N31: High | O31: Strong designer coverage. | P31: https://www.proveedores.com/proveedores/ocean-fragrances/ | Q31: Not contacted
A32: 25 | B32: Distribuidor Perfumes | C32: Spain | D32: Barcelona | E32: https://www.distribuidorperfumes.com | F32: From directory - verify | G32: https://www.distribuidorperfumes.com/ | H32: Via website | I32: +34 902 732 332 | J32: Gran Via de les Corts Catalanes 646, 08007 Barcelona | K32: Wholesaler + dropship (24-48h) | L32: Top-brand perfumes | N32: High | P32: https://www.proveedores.com/proveedores/distribuidor-perfumes/ | Q32: Not contacted
A33: 26 | B33: IGMACO Distribución Europa S.L. | C33: Spain | D33: Madrid | E33: https://www.igmaco.com | F33: From directory - verify | G33: https://www.igmaco.com | H33: Not public - use website contact page | I33: +34 915 .. (see website) | J33: Calle Núñez de Balboa 90, Madrid | K33: Wholesaler & distributor (est. 2004) | L33: Selective perfumes, cosmetics, hair care | N33: High | O33: Selective (designer) focus. | P33: https://oncosmetics.com/company/igmaco/ | Q33: Not contacted
A34: 27 | B34: Madallmes | C34: Spain | D34: Meliana (Valencia) | E34: https://madallmes.com | F34: From directory - verify | G34: https://madallmes.com | H34: Not public - use website contact page | I34: +34 963 218 502 | J34: Carrer Llanterners 10, 46133 Meliana | K34: Perfumery wholesaler | L34: 8,000+ original products | N34: Medium | P34: https://proveedores.com/proveedores/madallmes/ | Q34: Not contacted
A35: 28 | B35: Perfumes y Diseño (PYD) | C35: Spain | D35: Madrid | E35: https://www.pyd.es | F35: From directory - verify | G35: https://www.pyd.es | H35: pyd@pyd.es | J35: Calle Isla de Java 33, 28034 Madrid | K35: Licensee & brand distributor | L35: Distributes Cartier, Versace, Moschino; licences Tous, Scalpers | M35: Trade accounts | N35: Medium | O35: Official distributor. | P35: https://empresite.eleconomista.es/PERFUMES-DISENO-ESPANA.html | Q35: Not contacted
A36: 29 | B36: Orient Fragance | C36: Spain | D36: Barcelona | E36: https://www.orientfragance.com | F36: Confirmed | G36: https://www.orientfragance.com/en/pages/contact | H36: orientfragance@gmail.com | I36: +34 623 109 380 | J36: Santa Perpètua de Mogoda (by appointment) | K36: Official distributor Spain & Portugal | L36: Lattafa, Swiss Arabian etc. CPNP registered | M36: Wholesale registration form | N36: Medium | O36: Authorised distributor for Arabian brands. | P36: https://www.orientfragance.com/en/pages/contacto | Q36: Not contacted
A37: 30 | B37: GPD Central de Perfumería y Cosmética | C37: Spain | D37: Madrid | E37: https://gpd.es | F37: From directory - verify | G37: https://gpd.es | H37: Not public - use website contact page | J37: Calle de Orense 68, Madrid | K37: Wholesaler (35+ yrs) | L37: Perfumery, cosmetics, parapharmacy | N37: Medium | P37: https://oncosmetics.com/company/gpd-central-de-perfumeria-y-cosmetica/ | Q37: Not contacted
A38: 31 | B38: Mayorista Perfumería | C38: Spain | D38: Valdemoro (Madrid) | E38: https://mayoristaperfumeria.es | F38: From directory - verify | G38: https://mayoristaperfumeria.es | H38: Not public - use website contact page | J38: Calle Ibiza 8, Valdemoro | K38: Wholesale distributor (est. 1992) | L38: Branded & private-label perfume/cosmetics | N38: Medium | P38: https://oncosmetics.com/company/mayoristaperfumeria/ | Q38: Not contacted
A39: 32 | B39: Quisben Ibérica S.L. | C39: Spain | D39: San Sebastián de los Reyes (Madrid) | E39: https://www.quisben.com | F39: From directory - verify | G39: https://www.quisben.com | H39: Not public - use website contact page | J39: San Sebastián de los Reyes | K39: Importer & wholesaler | L39: Perfumes & deodorants; buys large lots | N39: Medium | O39: Possible job-lot source. | P39: https://oncosmetics.com/company/quisben-iberica-s-l/ | Q39: Not contacted
A40: 33 | B40: Beauty Way SL | C40: Spain | D40: Valencia & Ávila | E40: https://beautyway.es | F40: From directory - verify | G40: https://beautyway.es | H40: Not public - use website contact page | J40: Ávila | K40: Designer perfume distributor (est. 2022) | L40: Designer perfumes & gift sets | M40: No minimum order | N40: Low | O40: Very small (1 employee). | P40: https://oncosmetics.com/company/beauty-way-sl/ | Q40: Not contacted
...

Sheet UK Suppliers (non-EU)
A1: # | B1: Company | C1: Country | D1: City / Region | E1: Website | F1: Website Check | G1: Wholesale Sign-up / Contact Page | H1: Email | I1: Phone | J1: Address | K1: Supplier Type | L1: Brands / Focus | M1: MOQ / Terms | N1: Priority | O1: Notes / Risk Flags | P1: Source (where found) | Q1: Outreach Status | R1: Date Contacted | S1: Follow-up Date | T1: Response / Notes
A2: UK SUPPLIERS (non-EU - customs apply for EU stock) (3)
A3: 1 | B3: Shaneel Group | C3: United Kingdom | D3: Wembley, London | E3: https://www.shaneel.com | F3: From directory - verify | G3: https://www.shaneel.com | H3: Not public - use website contact page | J3: 78 Wembley Park Drive, Wembley | K3: Branded fine fragrance distributor (since 1986) | L3: Branded fine fragrance for independents; owns Designer Parfums, Mayfair | N3: High | P3: https://jobs.workable.com/companies/iKxrmDgx2D2P41Cmp6pAvV.md | Q3: Not contacted
A4: 2 | B4: Affinity Fragrances | C4: United Kingdom | E4: https://affinityfragrances.com | F4: From directory - verify | G4: https://affinityfragrances.com | H4: Not public - use website contact page | K4: Fragrance wholesaler | L4: Branded perfumes; UK distributor for Lionel Messi fragrances | N4: Medium | P4: https://retail-merchandiser.com/news/affinity-fragrances-focus-on-trust-agility-and-long-term-partnerships-is-driving-its-international-expansion/ | Q4: Not contacted
A5: 3 | B5: Fragrance Wholesale International Ltd | C5: United Kingdom | E5: Not found | F5: - | G5: https://find-and-update.company-information.service.gov.uk/company/14662527 | H5: Not public - use website contact page | J5: See Companies House | K5: SIC 46450 perfume wholesale | N5: Low | P5: https://find-and-update.company-information.service.gov.uk/company/14662527 | Q5: Not contacted

Sheet Outreach Email Template
A1: Subject: | B1: Wholesale account enquiry - Crowsons Global (branded fragrances)
A3: Body: | B3: Hello [Name / Team],
B4: I'm [Your Name] from Crowsons Global, a UK/EU distribution business. We're looking for a reliable wholesale partner for branded perfumes and aftershaves, which we resell through online marketplaces including Amazon.
B5: Could you please send:
B6: 1. Your current wholesale price list / stock list (in Excel if possible)
B7: 2. Your minimum order value and payment terms
B8: 3. Delivery times and costs to [UK / your EU warehouse country]
B9: 4. Confirmation that invoices show your full company details and VAT number, and whether they've been accepted for Amazon brand approvals before
B10: 5. Which brands you're an authorised distributor for, if any
B11: Our company details: [Company name, registration number, VAT/EORI number, address, website].
B12: I'm happy to start with a trial order and grow volume from there.
B13: Kind regards,
B14: [Name] | Crowsons Global | [Phone] | [Email]
